Traceback (most recent call last):
  File "c:\users\wilso\miniconda3\envs\sysidentpy\lib\site-packages\jupyter_cache\executors\utils.py", line 51, in single_nb_execution
    executenb(
  File "c:\users\wilso\miniconda3\envs\sysidentpy\lib\site-packages\nbclient\client.py", line 1117, in execute
    return NotebookClient(nb=nb, resources=resources, km=km, **kwargs).execute()
  File "c:\users\wilso\miniconda3\envs\sysidentpy\lib\site-packages\nbclient\util.py", line 78, in wrapped
    return just_run(coro(*args, **kwargs))
  File "c:\users\wilso\miniconda3\envs\sysidentpy\lib\site-packages\nbclient\util.py", line 57, in just_run
    return loop.run_until_complete(coro)
  File "c:\users\wilso\miniconda3\envs\sysidentpy\lib\asyncio\base_events.py", line 616, in run_until_complete
    return future.result()
  File "c:\users\wilso\miniconda3\envs\sysidentpy\lib\site-packages\nbclient\client.py", line 558, in async_execute
    await self.async_execute_cell(
  File "c:\users\wilso\miniconda3\envs\sysidentpy\lib\site-packages\nbclient\client.py", line 862, in async_execute_cell
    self._check_raise_for_error(cell, exec_reply)
  File "c:\users\wilso\miniconda3\envs\sysidentpy\lib\site-packages\nbclient\client.py", line 765, in _check_raise_for_error
    raise CellExecutionError.from_cell_and_msg(cell, exec_reply_content)
nbclient.exceptions.CellExecutionError: An error occurred while executing the following cell:
------------------
import numpy as np
import pandas as pd
from sysidentpy.simulation import SimulateNARMAX
from sysidentpy.metrics import root_relative_squared_error
from sysidentpy.utils.generate_data import get_siso_data
from sysidentpy.basis_function._basis_function import Polynomial
from sysidentpy.utils.display_results import results
from sysidentpy.utils.plotting import plot_residues_correlation, plot_results
from sysidentpy.residues.residues_correlation import compute_residues_autocorrelation, compute_cross_correlation
------------------

[1;31m---------------------------------------------------------------------------[0m
[1;31mModuleNotFoundError[0m                       Traceback (most recent call last)
[1;32m~\AppData\Local\Temp/ipykernel_40256/1659722353.py[0m in [0;36m<module>[1;34m[0m
[0;32m      1[0m [1;32mimport[0m [0mnumpy[0m [1;32mas[0m [0mnp[0m[1;33m[0m[1;33m[0m[0m
[0;32m      2[0m [1;32mimport[0m [0mpandas[0m [1;32mas[0m [0mpd[0m[1;33m[0m[1;33m[0m[0m
[1;32m----> 3[1;33m [1;32mfrom[0m [0msysidentpy[0m[1;33m.[0m[0msimulation[0m [1;32mimport[0m [0mSimulateNARMAX[0m[1;33m[0m[1;33m[0m[0m
[0m[0;32m      4[0m [1;32mfrom[0m [0msysidentpy[0m[1;33m.[0m[0mmetrics[0m [1;32mimport[0m [0mroot_relative_squared_error[0m[1;33m[0m[1;33m[0m[0m
[0;32m      5[0m [1;32mfrom[0m [0msysidentpy[0m[1;33m.[0m[0mutils[0m[1;33m.[0m[0mgenerate_data[0m [1;32mimport[0m [0mget_siso_data[0m[1;33m[0m[1;33m[0m[0m

[1;31mModuleNotFoundError[0m: No module named 'sysidentpy.simulation'
ModuleNotFoundError: No module named 'sysidentpy.simulation'

